Workbook

Sheet INDICADOR 2025
H8: ROTACIÓN DE PERSONAL 2025
B10: ENERO | C10: FEBRERO | D10: MARZO | E10: ABRIL | F10: MAYO | G10: JUNIO | H10: JULIO | I10: AGOSTO | J10: SEPT | K10: OCT | L10: NOV | M10: DIC | N10: TOTALES
A11: ALTAS | B11: =SUM('INDICADOR X SUCURSAL 2025'!B11+'INDICADOR X SUCURSAL 2025'!B20+'INDICADOR X SUCURSAL 2025'!B29+'INDICADOR X SUCURSAL 2025'!B38+'INDICADOR X SUCURSAL 2025'!B46+'INDICADOR X SUCURSAL 2025'!B55+'INDICADOR X SUCURSAL 2025'!B64+'INDICADOR X SUCURSAL 2025'!B72+'INDICADOR X SUCURSAL 2025'!B81+'INDICADOR X SUCURSAL 2025'!B90+'INDICADOR X SUCURSAL 2025'!B100+'INDICADOR X SUCURSAL 2025'!B111+'INDICADOR X SUCURSAL 2025'!B121+'INDICADOR X SUCURSAL 2025'!B132) -> 22 | C11: =SUM('INDICADOR X SUCURSAL 2025'!C11+'INDICADOR X SUCURSAL 2025'!C20+'INDICADOR X SUCURSAL 2025'!C29+'INDICADOR X SUCURSAL 2025'!C38+'INDICADOR X SUCURSAL 2025'!C46+'INDICADOR X SUCURSAL 2025'!C55+'INDICADOR X SUCURSAL 2025'!C64+'INDICADOR X SUCURSAL 2025'!C72+'INDICADOR X SUCURSAL 2025'!C81+'INDICADOR X SUCURSAL 2025'!C90+'INDICADOR X SUCURSAL 2025'!C100+'INDICADOR X SUCURSAL 2025'!C111+'INDICADOR X SUCURSAL 2025'!C121+'INDICADOR X SUCURSAL 2025'!C132+'INDICADOR X SUCURSAL 2025'!C141) -> 14 | D11: =SUM('INDICADOR X SUCURSAL 2025'!D11+'INDICADOR X SUCURSAL 2025'!D20+'INDICADOR X SUCURSAL 2025'!D29+'INDICADOR X SUCURSAL 2025'!D38+'INDICADOR X SUCURSAL 2025'!D46+'INDICADOR X SUCURSAL 2025'!D55+'INDICADOR X SUCURSAL 2025'!D64+'INDICADOR X SUCURSAL 2025'!D72+'INDICADOR X SUCURSAL 2025'!D81+'INDICADOR X SUCURSAL 2025'!D90+'INDICADOR X SUCURSAL 2025'!D100+'INDICADOR X SUCURSAL 2025'!D111+'INDICADOR X SUCURSAL 2025'!D121+'INDICADOR X SUCURSAL 2025'!D132+'INDICADOR X SUCURSAL 2025'!D141) -> 11 | E11: =SUM('INDICADOR X SUCURSAL 2025'!E11+'INDICADOR X SUCURSAL 2025'!E20+'INDICADOR X SUCURSAL 2025'!E29+'INDICADOR X SUCURSAL 2025'!E38+'INDICADOR X SUCURSAL 2025'!E46+'INDICADOR X SUCURSAL 2025'!E55+'INDICADOR X SUCURSAL 2025'!E64+'INDICADOR X SUCURSAL 2025'!E72+'INDICADOR X SUCURSAL 2025'!E81+'INDICADOR X SUCURSAL 2025'!E90+'INDICADOR X SUCURSAL 2025'!E100+'INDICADOR X SUCURSAL 2025'!E111+'INDICADOR X SUCURSAL 2025'!E121+'INDICADOR X SUCURSAL 2025'!E132+'INDICADOR X SUCURSAL 2025'!E141) -> 9 | F11: =SUM('INDICADOR X SUCURSAL 2025'!F141+'INDICADOR X SUCURSAL 2025'!F132+'INDICADOR X SUCURSAL 2025'!F121+'INDICADOR X SUCURSAL 2025'!F111+'INDICADOR X SUCURSAL 2025'!F100+'INDICADOR X SUCURSAL 2025'!F90+'INDICADOR X SUCURSAL 2025'!F81+'INDICADOR X SUCURSAL 2025'!F72+'INDICADOR X SUCURSAL 2025'!F64+'INDICADOR X SUCURSAL 2025'!F55+'INDICADOR X SUCURSAL 2025'!F46+'INDICADOR X SUCURSAL 2025'!F38+'INDICADOR X SUCURSAL 2025'!F29+'INDICADOR X SUCURSAL 2025'!F20+'INDICADOR X SUCURSAL 2025'!F11) -> 9 | G11: =SUM('INDICADOR X SUCURSAL 2025'!G11+'INDICADOR X SUCURSAL 2025'!G20+'INDICADOR X SUCURSAL 2025'!G29+'INDICADOR X SUCURSAL 2025'!G38+'INDICADOR X SUCURSAL 2025'!G46+'INDICADOR X SUCURSAL 2025'!G55+'INDICADOR X SUCURSAL 2025'!G64+'INDICADOR X SUCURSAL 2025'!G72+'INDICADOR X SUCURSAL 2025'!G81+'INDICADOR X SUCURSAL 2025'!G90+'INDICADOR X SUCURSAL 2025'!G100+'INDICADOR X SUCURSAL 2025'!G111+'INDICADOR X SUCURSAL 2025'!G121+'INDICADOR X SUCURSAL 2025'!G132+'INDICADOR X SUCURSAL 2025'!G141) -> 14 | H11: =SUM('INDICADOR X SUCURSAL 2025'!H11+'INDICADOR X SUCURSAL 2025'!H20+'INDICADOR X SUCURSAL 2025'!H29+'INDICADOR X SUCURSAL 2025'!H38+'INDICADOR X SUCURSAL 2025'!H46+'INDICADOR X SUCURSAL 2025'!H55+'INDICADOR X SUCURSAL 2025'!H64+'INDICADOR X SUCURSAL 2025'!H72+'INDICADOR X SUCURSAL 2025'!H81+'INDICADOR X SUCURSAL 2025'!H90+'INDICADOR X SUCURSAL 2025'!H100+'INDICADOR X SUCURSAL 2025'!H111+'INDICADOR X SUCURSAL 2025'!H121+'INDICADOR X SUCURSAL 2025'!H132+'INDICADOR X SUCURSAL 2025'!H141) -> 22 | I11: =SUM('INDICADOR X SUCURSAL 2025'!I11+'INDICADOR X SUCURSAL 2025'!I20+'INDICADOR X SUCURSAL 2025'!I29+'INDICADOR X SUCURSAL 2025'!I38+'INDICADOR X SUCURSAL 2025'!I46+'INDICADOR X SUCURSAL 2025'!I55+'INDICADOR X SUCURSAL 2025'!I64+'INDICADOR X SUCURSAL 2025'!I72+'INDICADOR X SUCURSAL 2025'!I81+'INDICADOR X SUCURSAL 2025'!I90+'INDICADOR X SUCURSAL 2025'!I100+'INDICADOR X SUCURSAL 2025'!I111+'INDICADOR X SUCURSAL 2025'!I121+'INDICADOR X SUCURSAL 2025'!I132+'INDICADOR X SUCURSAL 2025'!I141) -> 7 | J11: 16 | K11: ='INDICADOR X SUCURSAL 2025'!K11+'INDICADOR X SUCURSAL 2025'!K20+'INDICADOR X SUCURSAL 2025'!K29+'INDICADOR X SUCURSAL 2025'!K38+'INDICADOR X SUCURSAL 2025'!K46+'INDICADOR X SUCURSAL 2025'!K55+'INDICADOR X SUCURSAL 2025'!K64+'INDICADOR X SUCURSAL 2025'!K72+'INDICADOR X SUCURSAL 2025'!K81+'INDICADOR X SUCURSAL 2025'!K90+'INDICADOR X SUCURSAL 2025'!K100+'INDICADOR X SUCURSAL 2025'!K111+'INDICADOR X SUCURSAL 2025'!K121+'INDICADOR X SUCURSAL 2025'!K132+'INDICADOR X SUCURSAL 2025'!K141 -> 15 | L11: =SUM('INDICADOR X SUCURSAL 2025'!L11+'INDICADOR X SUCURSAL 2025'!L20+'INDICADOR X SUCURSAL 2025'!L29+'INDICADOR X SUCURSAL 2025'!L38+'INDICADOR X SUCURSAL 2025'!L46+'INDICADOR X SUCURSAL 2025'!L55+'INDICADOR X SUCURSAL 2025'!L64+'INDICADOR X SUCURSAL 2025'!L72+'INDICADOR X SUCURSAL 2025'!L81+'INDICADOR X SUCURSAL 2025'!L90+'INDICADOR X SUCURSAL 2025'!L100+'INDICADOR X SUCURSAL 2025'!L111+'INDICADOR X SUCURSAL 2025'!L121+'INDICADOR X SUCURSAL 2025'!L132+'INDICADOR X SUCURSAL 2025'!L141+'INDICADOR X SUCURSAL 2025'!L150) -> 8 | N11: =SUM(B11:M11) -> 147
A12: BAJAS | B12: ='INDICADOR X SUCURSAL 2025'!D155 -> 13 | C12: ='INDICADOR X SUCURSAL 2025'!D156 -> 9 | D12: ='INDICADOR X SUCURSAL 2025'!D157 -> 5 | E12: ='INDICADOR X SUCURSAL 2025'!D158 -> 15 | F12: ='INDICADOR X SUCURSAL 2025'!D159 -> 13 | G12: ='INDICADOR X SUCURSAL 2025'!D160 -> 18 | H12: ='INDICADOR X SUCURSAL 2025'!D161 -> 13 | I12: ='INDICADOR X SUCURSAL 2025'!D162 -> 10 | J12: 12 | K12: ='INDICADOR X SUCURSAL 2025'!K12+'INDICADOR X SUCURSAL 2025'!K21+'INDICADOR X SUCURSAL 2025'!K30+'INDICADOR X SUCURSAL 2025'!K39+'INDICADOR X SUCURSAL 2025'!K47+'INDICADOR X SUCURSAL 2025'!K56+'INDICADOR X SUCURSAL 2025'!K65+'INDICADOR X SUCURSAL 2025'!K73+'INDICADOR X SUCURSAL 2025'!K82+'INDICADOR X SUCURSAL 2025'!K91+'INDICADOR X SUCURSAL 2025'!K101+'INDICADOR X SUCURSAL 2025'!K112+'INDICADOR X SUCURSAL 2025'!K122+'INDICADOR X SUCURSAL 2025'!K133+'INDICADOR X SUCURSAL 2025'!K142 -> 16 | L12: ='INDICADOR X SUCURSAL 2025'!L12+'INDICADOR X SUCURSAL 2025'!L21+'INDICADOR X SUCURSAL 2025'!L30+'INDICADOR X SUCURSAL 2025'!L39+'INDICADOR X SUCURSAL 2025'!L47+'INDICADOR X SUCURSAL 2025'!L56+'INDICADOR X SUCURSAL 2025'!L65+'INDICADOR X SUCURSAL 2025'!L73+'INDICADOR X SUCURSAL 2025'!L82+'INDICADOR X SUCURSAL 2025'!L91+'INDICADOR X SUCURSAL 2025'!L101+'INDICADOR X SUCURSAL 2025'!L112+'INDICADOR X SUCURSAL 2025'!L122+'INDICADOR X SUCURSAL 2025'!L133+'INDICADOR X SUCURSAL 2025'!L142 -> 6 | M12: ='INDICADOR X SUCURSAL 2025'!N156 -> 0 | N12: 119
A13: PLANTILLA | B13: =A14+B11-B12 -> 136 | C13: =B13+C11-C12 -> 141 | D13: =C13+D11-D12 -> 147 | E13: =D13+E11-E12 -> 141 | F13: =E13+F11-F12 -> 137 | G13: =F13+G11-G12 -> 133 | H13: =G13+H11-H12 -> 142 | I13: =H13+I11-I12 -> 139 | J13: =I13+J11-J12 -> 143 | ... L13: =K13+L11-L12 -> 144 | N13: 144
A14: 127
A15: ROTACIÓN | B15: =B12*100/B13 -> 9.5588235 | C15: =C12*100/C13 -> 6.3829787 | D15: =D12*100/D13 -> 3.4013605 | E15: =E12*100/E13 -> 10.638298 | F15: =F12*100/F13 -> 9.4890511 | G15: =G12*100/G13 -> 13.533835 | H15: =H12*100/H13 -> 9.1549296 | I15: =I12*100/I13 -> 7.1942446 | ... L15: =L12*100/L13 -> 4.1666667 | N15: 7.55 | O15: PROMEDIO MENSUAL
N16: =N12*100/N13 -> 82.638889 | O16: ROTACIÓN ANUAL
H25: ROTACIÓN DE PERSONAL 2025
B27: ENERO | C27: FEBRERO | D27: MARZO | E27: ABRIL | F27: MAYO | G27: JUNIO | H27: JULIO | I27: AGOSTO | J27: SEPT | K27: OCT | L27: NOV | M27: DIC | N27: TOTALES
A28: ALTAS | B28: 19 | G28: 9 | H28: 12 | I28: 6 | K28: 3 | L28: 7 | N28: =SUM(B28:M28) -> 56
A29: BAJAS | B29: 11 | I29: 10 | K29: 10 | L29: 7 | N29: =SUM(B29:M29) -> 38
A30: PLANTILLA | B30: =A31+B28-B29 -> 87 | I30: =A31+I28-I29 -> 75 | J30: 77 | K30: =J30+K28-K29 -> 70 | L30: =K30+L28-L29 -> 70 | N30: =A31+N28-N29 -> 97
A31: 79
A32: ROTACIÓN | B32: =B29*100/B30 -> 12.643678 | I32: =I29*100/I30 -> 13.333333 | J32: =J29*100/J30 -> 0 | K32: =K29*100/K30 -> 14.285714 | L32: =L29*100/L30 -> 10 | N32: =B32 -> 12.643678 | O32: PROMEDIO MENSUAL
N33: =N29*100/N30 -> 39.175258 | O33: ROTACIÓN ANUAL
F44: CORPORATIVO
H47: ROTACIÓN DE PERSONAL 2025
B49: ENERO | C49: FEBRERO | D49: MARZO | E49: ABRIL | F49: MAYO | G49: JUNIO | H49: JULIO | I49: AGOSTO | J49: SEPT | K49: OCT | L49: NOV | M49: DIC | N49: TOTALES
A50: ALTAS | B50: 1 | C50: 0 | D50: 2 | E50: 3 | F50: 2 | G50: 4 | H50: 2 | I50: 3 | J50: 0 | K50: 6 | L50: 1 | N50: =SUM(B50:M50) -> 24
A51: BAJAS | B51: 4 | C51: 5 | D51: 4 | E51: 2 | F51: 2 | G51: 2 | H51: 2 | I51: 3 | J51: 3 | K51: 0 | L51: 1 | N51: 19
A52: PLANTILLA | B52: =A53+B50-B51 -> 39 | C52: =B52+C50-C51 -> 34 | D52: =C52+D50-D51 -> 32 | E52: =D52+E50-E51 -> 33 | F52: =E52+F50-F51 -> 33 | G52: =F52+G50-G51 -> 35 | H52: =G52+H50-H51 -> 35 | I52: =H52+I50-I51 -> 35 | J52: =I52+J50-J51 -> 32 | ... L52: =K52+L50-L51 -> 38 | N52: 38
A53: 42
A54: ROTACIÓN | B54: =B51*100/B52 -> 10.25641 | C54: =C51*100/C52 -> 14.705882 | D54: =D51*100/D52 -> 12.5 | E54: =E51*100/E52 -> 6.0606061 | F54: =F51*100/F52 -> 6.0606061 | G54: =G51*100/G52 -> 5.7142857 | H54: =H51*100/H52 -> 5.7142857 | I54: =I51*100/I52 -> 8.5714286 | ... L54: =L51*100/L52 -> 2.6315789 | N54: 8.7 | O54: PROMEDIO MENSUAL
N55: =N51*100/N52 -> 50 | O55: ROTACIÓN ANUAL
H65: ROTACIÓN DE PERSONAL 2025
B67: ENERO | C67: FEBRERO | D67: MARZO | E67: ABRIL | F67: MAYO | G67: JUNIO | H67: JULIO | I67: AGOSTO | J67: SEPT | K67: OCT | L67: NOV | M67: DIC | N67: TOTALES
A68: ALTAS | B68: 0 | C68: 0 | D68: 0 | E68: 0 | F68: 0 | G68: 15 | H68: 3 | I68: 2 | J68: 3 | K68: 1 | L68: 0 | N68: =SUM(B68:M68) -> 24
A69: BAJAS | B69: 0 | C69: 0 | D69: 0 | E69: 0 | F69: 0 | G69: 4 | H69: 2 | I69: 6 | J69: 3 | K69: 2 | L69: 0 | N69: =SUM(B69:M69) -> 17
A70: PLANTILLA | B70: 0 | C70: 0 | D70: 0 | E70: 0 | F70: 0 | G70: =G68-G69 -> 11 | H70: =G70+H68-H69 -> 12 | I70: =H70+I68-I69 -> 8 | J70: =I70+J68-J69 -> 8 | K70: =J70+K68-K69 -> 7 | L70: =K70+L68-L69 -> 7 | N70: =N68-N69 -> 7
A71: 15
A72: ROTACIÓN | B72: =B69*100/B70 -> #DIV/0! | C72: =C69*100/C70 -> #DIV/0! | D72: =D69*100/D70 -> #DIV/0! | E72: =E69*100/E70 -> #DIV/0! | F72: =F69*100/F70 -> #DIV/0! | G72: =G69*100/G70 -> 36.363636 | H72: =H69*100/H70 -> 16.666667 | I72: =I69*100/I70 -> 75 | ... L72: =L69*100/L70 -> 0 | N72: 41.38 | O72: PROMEDIO MENSUAL
N73: =15*100/8 -> 187.5 | O73: ROTACIÓN ANUAL

Sheet INDICADOR X SUCURSAL 2025
C2: ROTACIÓN POR SUCURSALES 2025
F9: ATLACOMULCO
B10: ENERO | C10: FEBRERO | D10: MARZO | E10: ABRIL | F10: MAYO | G10: JUNIO | H10: JULIO | I10: AGOSTO | J10: SEPT | K10: OCT | L10: NOV | M10: DIC | N10: TOTALES
A11: ALTAS | B11: 0 | C11: 2 | D11: 2 | E11: 1 | F11: 1 | G11: 1 | H11: 1 | I11: 1 | J11: 0 | K11: 1 | L11: 1 | M11: 0 | N11: =SUM(B11:M11) -> 11
A12: BAJAS | B12: 1 | C12: 1 | D12: 1 | E12: 2 | F12: 0 | G12: 0 | H12: 2 | I12: 1 | J12: 2 | K12: 0 | L12: 0 | M12: 0 | N12: =SUM(B12:M12) -> 10
A13: PLANTILLA | B13: =A14+B11-B12 -> 8 | C13: =B13+C11-C12 -> 9 | D13: =C13+D11-D12 -> 10 | E13: =D13+E11-E12 -> 9 | F13: =E13+F11-F12 -> 10 | G13: =F13+G11-G12 -> 11 | H13: =G13+H11-H12 -> 10 | I13: =H13+I11-I12 -> 10 | J13: =I13+J11-J12 -> 8 | ... M13: =L13+M11-M12 -> 10 | N13: =A14+N11-N12 -> 10
A14: 9
A15: ROTACIÓN | B15: =(B12*100/B13)/3 -> 4.1666667 | C15: =C12*100/C13 -> 11.111111 | D15: =D12*100/D13 -> 10 | E15: =E12*100/E13 -> 22.222222 | F15: =F12*100/F13 -> 0 | G15: =G12*100/G13 -> 0 | H15: =H12*100/H13 -> 20 | I15: =I12*100/I13 -> 10 | J15: =J12*100/J13 -> 25 | ... M15: =M12*100/M13 -> 0 | N15: 8.54 | O15: PROMEDIO MENSUAL
N16: =N12*100/N13 -> 100 | O16: ROTACIÓN ANUAL
F18: ATLIXCO
B19: ENERO | C19: FEBRERO | D19: MARZO | E19: ABRIL | F19: MAYO | G19: JUNIO | H19: JULIO | I19: AGOSTO | J19: SEPT | K19: OCT | L19: NOV | M19: DIC | N19: TOTALES
A20: ALTAS | B20: 1 | C20: 0 | D20: 0 | E20: 0 | F20: 1 | G20: 1 | H20: 1 | I20: 1 | J20: 1 | K20: 1 | L20: 0 | M20: 0 | N20: =SUM(B20:M20) -> 7
A21: BAJAS | B21: 1 | C21: 1 | D21: 0 | E21: 0 | F21: 1 | G21: 1 | H21: 1 | I21: 0 | J21: 1 | K21: 0 | L21: 1 | M21: 0 | N21: =SUM(B21:M21) -> 7
A22: PLANTILLA | B22: =A23+B20-B21 -> 7 | C22: =B22+C20-C21 -> 6 | D22: =C22+D20-D21 -> 6 | E22: =D22+E20-E21 -> 6 | F22: =E22+F20-F21 -> 6 | G22: =F22+G20-G21 -> 6 | H22: =G22+H20-H21 -> 6 | I22: =H22+I20-I21 -> 7 | J22: =I22+J20-J21 -> 7 | ... M22: =L22+M20-M21 -> 7 | N22: =A23+N20-N21 -> 7
A23: 7
A24: ROTACIÓN | B24: =B21*100/B22 -> 14.285714 | C24: =C21*100/C22 -> 16.666667 | D24: =D21*100/D22 -> 0 | E24: =E21*100/E22 -> 0 | F24: =F21*100/F22 -> 16.666667 | G24: =G21*100/G22 -> 16.666667 | H24: =H21*100/H22 -> 16.666667 | I24: =I21*100/I22 -> 0 | ... M24: =M21*100/M22 -> 0 | N24: 9.13 | O24: PROMEDIO MENSUAL
N25: =N21*100/N22 -> 100 | O25: ROTACIÓN ANUAL
F27: CORDOBA
B28: ENERO | C28: FEBRERO | D28: MARZO | E28: ABRIL | F28: MAYO | G28: JUNIO | H28: JULIO | I28: AGOSTO | J28: SEPT | K28: OCT | L28: NOV | M28: DIC | N28: TOTALES
A29: ALTAS | B29: 2 | C29: 1 | D29: 1 | E29: 0 | F29: 1 | G29: 0 | H29: 0 | I29: 0 | J29: 3 | K29: 2 | L29: 0 | M29: 1 | N29: =SUM(B29:M29) -> 11
A30: BAJAS | B30: 0 | C30: 0 | D30: 1 | E30: 1 | F30: 0 | G30: 0 | H30: 0 | I30: 1 | J30: 2 | K30: 0 | L30: 0 | M30: 1 | N30: =SUM(B30:M30) -> 6
A31: PLANTILLA | B31: =A32+B29-B30 -> 17 | C31: =B31+C29-C30 -> 18 | D31: =C31+D29-D30 -> 18 | E31: =D31+E29-E30 -> 17 | F31: =E31+F29-F30 -> 18 | G31: =F31+G29-G30 -> 18 | H31: =G31+H29-H30 -> 18 | I31: =H31+I29-I30 -> 17 | J31: =I31+J29-J30 -> 18 | ... M31: =L31+M29-M30 -> 20 | N31: =A32+N29-N30 -> 20
A32: 15
A33: ROTACIÓN | B33: =B30*100/B31 -> 0 | C33: =C30*100/C31 -> 0 | D33: =D30*100/D31 -> 5.5555556 | E33: =E30*100/E31 -> 5.8823529 | F33: =F30*100/F31 -> 0 | G33: =G30*100/G31 -> 0 | H33: =H30*100/H31 -> 0 | I33: =I30*100/I31 -> 5.8823529 | ... M33: =M30*100/M31 -> 5 | N33: 2.79 | O33: PROMEDIO MENSUAL
N34: =N30*100/N31 -> 30 | O34: ROTACIÓN ANUAL
F36: CUERNAVACA
B37: ENERO | C37: FEBRERO | D37: MARZO | E37: ABRIL | F37: MAYO | G37: JUNIO | H37: JULIO | I37: AGOSTO | J37: SEPT | K37: OCT | L37: NOV | M37: DIC | N37: TOTALES
A38: ALTAS | B38: 2 | C38: 0 | D38: 0 | E38: 3 | F38: 0 | G38: 2 | H38: 1 | I38: 0 | J38: 1 | K38: 3 | L38: 2 | M38: 2 | N38: =SUM(B38:M38) -> 16
A39: BAJAS | B39: 2 | C39: 0 | D39: 0 | E39: 3 | F39: 0 | G39: 2 | H39: 1 | I39: 0 | J39: 2 | K39: 3 | L39: 0 | M39: 0 | N39: =SUM(B39:M39) -> 13
A40: PLANTILLA | B40: =A41+B38-B39 -> 9 | C40: =B40+C38-C39 -> 9 | D40: =C40+D38-D39 -> 9 | E40: =D40+E38-E39 -> 9 | F40: =E40+F38-F39 -> 9 | G40: =F40+G38-G39 -> 9 | H40: =G40+H38-H39 -> 9 | I40: =H40+I38-I39 -> 9 | J40: =I40+J38-J39 -> 8 | ... M40: =L40+M38-M39 -> 12 | N40: =A41+N38-N39 -> 12
A41: 9
A42: ROTACIÓN | B42: =B39*100/B40 -> 22.222222 | C42: =C39*100/C40 -> 0 | D42: =D39*100/D40 -> 0 | E42: =E39*100/E40 -> 33.333333 | F42: =F39*100/F40 -> 0 | G42: =G39*100/G40 -> 22.222222 | H42: =H39*100/H40 -> 11.111111 | I42: =I39*100/I40 -> 0 | ... M42: =M39*100/M40 -> 0 | N42: 12.62 | O42: PROMEDIO MENSUAL
N43: =N39*100/N40 -> 108.33333 | O43: ROTACIÓN ANUAL
F44: HUAMANTLA
B45: ENERO | C45: FEBRERO | D45: MARZO | E45: ABRIL | F45: MAYO | G45: JUNIO | H45: JULIO | I45: AGOSTO | J45: SEPT | K45: OCT | L45: NOV | M45: DIC | N45: TOTALES
A46: ALTAS | B46: 1 | C46: 1 | D46: 0 | E46: 0 | F46: 1 | G46: 4 | H46: 4 | I46: 1 | J46: 2 | K46: 3 | L46: 0 | M46: 0 | N46: =SUM(B46:M46) -> 17
A47: BAJAS | B47: 1 | C47: 0 | D47: 0 | E47: 3 | F47: 4 | G47: 4 | H47: 2 | I47: 0 | J47: 0 | K47: 3 | L47: 2 | M47: 0 | N47: =SUM(B47:M47) -> 19
A48: PLANTILLA | B48: =A49+B46-B47 -> 11 | C48: =B48+C46-C47 -> 12 | D48: =C48+D46-D47 -> 12 | E48: =D48+E46-E47 -> 9 | F48: =E48+F46-F47 -> 6 | G48: =F48+G46-G47 -> 6 | H48: =G48+H46-H47 -> 8 | I48: =H48+I46-I47 -> 9 | J48: =I48+J46-J47 -> 11 | ... M48: =L48+M46-M47 -> 9 | N48: =A49+N46-N47 -> 9
A49: 11
A50: ROTACIÓN | B50: =B47*100/B48 -> 9.0909091 | C50: =C47*100/C48 -> 0 | D50: =D47*100/D48 -> 0 | E50: =E47*100/E48 -> 33.333333 | F50: =F47*100/F48 -> 66.666667 | G50: =G47*100/G48 -> 66.666667 | H50: =H47*100/H48 -> 25 | I50: =I47*100/I48 -> 0 | ... M50: =M47*100/M48 -> 0 | N50: 20.85 | O50: PROMEDIO MENSUAL
...

Sheet SUCURSALES 2026
C2: ROTACIÓN POR SUCURSALES 2026
F9: ATLACOMULCO
B10: ENERO | C10: FEBRERO | D10: MARZO | E10: ABRIL | F10: MAYO | G10: JUNIO | H10: JULIO | I10: AGOSTO | J10: SEPT | K10: OCT | L10: NOV | M10: DIC | N10: TOTALES
A11: ALTAS | B11: 0 | C11: 2 | D11: 1 | E11: 1 | F11: 0 | N11: =SUM(B11:M11) -> 4
A12: BAJAS | B12: 3 | C12: 0 | D12: 1 | E12: 0 | F12: 0 | N12: =SUM(B12:M12) -> 4
A13: PLANTILLA | B13: =A14+B11-B12 -> 6 | C13: =B13+C11-C12 -> 8 | D13: =C13+D11-D12 -> 8 | E13: =D13+E11-E12 -> 9 | F13: =E13+F11-F12 -> 9 | N13: =A14+N11-N12 -> 9
A14: 9
A15: ROTACIÓN | B15: =(B12*100/B13)/3 -> 16.666667 | C15: =C12*100/C13 -> 0 | D15: =D12*100/D13 -> 12.5 | E15: =E12*100/E13 -> 0 | F15: =F12*100/F13 -> 0 | G15: =G12*100/G13 -> #DIV/0! | H15: =H12*100/H13 -> #DIV/0! | I15: =I12*100/I13 -> #DIV/0! | J15: =J12*100/J13 -> #DIV/0! | ... M15: =M12*100/M13 -> #DIV/0! | N15: 5.83 | O15: PROMEDIO MENSUAL
N16: =N12*100/N13 -> 44.444444 | O16: ROTACIÓN ANUAL
F18: ATLIXCO
B19: ENERO | C19: FEBRERO | D19: MARZO | E19: ABRIL | F19: MAYO | G19: JUNIO | H19: JULIO | I19: AGOSTO | J19: SEPT | K19: OCT | L19: NOV | M19: DIC | N19: TOTALES
A20: ALTAS | B20: 2 | C20: 1 | D20: 0 | E20: 0 | F20: 0 | N20: =SUM(B20:M20) -> 3
A21: BAJAS | B21: 1 | C21: 0 | D21: 0 | E21: 0 | F21: 0 | N21: =SUM(B21:M21) -> 1
A22: PLANTILLA | B22: =A23+B20-B21 -> 8 | C22: =B22+C20-C21 -> 9 | D22: =C22+D20-D21 -> 9 | E22: =D22+E20-E21 -> 9 | F22: =E22+F20-F21 -> 9 | N22: =A23+N20-N21 -> 9
A23: 7
A24: ROTACIÓN | B24: =B21*100/B22 -> 12.5 | C24: =C21*100/C22 -> 0 | D24: =D21*100/D22 -> 0 | E24: =E21*100/E22 -> 0 | F24: =F21*100/F22 -> 0 | G24: =G21*100/G22 -> #DIV/0! | H24: =H21*100/H22 -> #DIV/0! | I24: =I21*100/I22 -> #DIV/0! | ... M24: =M21*100/M22 -> #DIV/0! | N24: 2.5 | O24: PROMEDIO MENSUAL
N25: =N21*100/N22 -> 11.111111 | O25: ROTACIÓN ANUAL
F27: CORDOBA
B28: ENERO | C28: FEBRERO | D28: MARZO | E28: ABRIL | F28: MAYO | G28: JUNIO | H28: JULIO | I28: AGOSTO | J28: SEPT | K28: OCT | L28: NOV | M28: DIC | N28: TOTALES
A29: ALTAS | B29: 0 | C29: 0 | D29: 0 | E29: 0 | F29: 0 | N29: =SUM(B29:M29) -> 0
A30: BAJAS | B30: 0 | C30: 0 | D30: 0 | E30: 1 | F30: 0 | N30: =SUM(B30:M30) -> 1
A31: PLANTILLA | B31: =A32+B29-B30 -> 20 | C31: =B31+C29-C30 -> 20 | D31: =C31+D29-D30 -> 20 | E31: =D31+E29-E30 -> 19 | F31: =E31+F29-F30 -> 19 | N31: =A32+N29-N30 -> 19
A32: 20
A33: ROTACIÓN | B33: =B30*100/B31 -> 0 | C33: =C30*100/C31 -> 0 | D33: =D30*100/D31 -> 0 | E33: =E30*100/E31 -> 5.2631579 | F33: =F30*100/F31 -> 0 | G33: =G30*100/G31 -> #DIV/0! | H33: =H30*100/H31 -> #DIV/0! | I33: =I30*100/I31 -> #DIV/0! | ... M33: =M30*100/M31 -> #DIV/0! | N33: 1.05 | O33: PROMEDIO MENSUAL
N34: =N30*100/N31 -> 5.2631579 | O34: ROTACIÓN ANUAL
F36: CUERNAVACA
B37: ENERO | C37: FEBRERO | D37: MARZO | E37: ABRIL | F37: MAYO | G37: JUNIO | H37: JULIO | I37: AGOSTO | J37: SEPT | K37: OCT | L37: NOV | M37: DIC | N37: TOTALES
A38: ALTAS | B38: 4 | C38: 1 | D38: 1 | E38: 1 | F38: 3 | N38: =SUM(B38:M38) -> 10
A39: BAJAS | B39: 4 | C39: 2 | D39: 1 | E39: 2 | F39: 3 | N39: =SUM(B39:M39) -> 12
A40: PLANTILLA | B40: =A41+B38-B39 -> 8 | C40: =B40+C38-C39 -> 7 | D40: =C40+D38-D39 -> 7 | E40: =D40+E38-E39 -> 6 | F40: =E40+F38-F39 -> 6 | N40: =A41+N38-N39 -> 6
A41: 8
A42: ROTACIÓN | B42: =B39*100/B40 -> 50 | C42: =C39*100/C40 -> 28.571429 | D42: =D39*100/D40 -> 14.285714 | E42: =E39*100/E40 -> 33.333333 | F42: =F39*100/F40 -> 50 | G42: =G39*100/G40 -> #DIV/0! | H42: =H39*100/H40 -> #DIV/0! | I42: =I39*100/I40 -> #DIV/0! | ... M42: =M39*100/M40 -> #DIV/0! | N42: 35.24 | O42: PROMEDIO MENSUAL
N43: =N39*100/N40 -> 200 | O43: ROTACIÓN ANUAL
F44: HUAMANTLA
B45: ENERO | C45: FEBRERO | D45: MARZO | E45: ABRIL | F45: MAYO | G45: JUNIO | H45: JULIO | I45: AGOSTO | J45: SEPT | K45: OCT | L45: NOV | M45: DIC | N45: TOTALES
A46: ALTAS | B46: 3 | C46: 2 | D46: 0 | E46: 2 | F46: 0 | N46: =SUM(B46:M46) -> 7
A47: BAJAS | B47: 3 | C47: 1 | D47: 3 | E47: 0 | F47: 0 | N47: =SUM(B47:M47) -> 7
A48: PLANTILLA | B48: =A49+B46-B47 -> 9 | C48: =B48+C46-C47 -> 10 | D48: =C48+D46-D47 -> 7 | E48: =D48+E46-E47 -> 9 | F48: =E48+F46-F47 -> 9 | N48: =A49+N46-N47 -> 9
A49: 9
A50: ROTACIÓN | B50: =B47*100/B48 -> 33.333333 | C50: =C47*100/C48 -> 10 | D50: =D47*100/D48 -> 42.857143 | E50: =E47*100/E48 -> 0 | F50: =F47*100/F48 -> 0 | G50: =G47*100/G48 -> #DIV/0! | H50: =H47*100/H48 -> #DIV/0! | I50: =I47*100/I48 -> #DIV/0! | ... M50: =M47*100/M48 -> #DIV/0! | N50: 17.24 | O50: PROMEDIO MENSUAL
...
